[2017-09-15 10:42:24,028] [werkzeug] [INFO] 87  * Restarting with stat
[2017-09-15 10:42:24,267] [werkzeug] [WARNING] 87  * Debugger is active!
[2017-09-15 10:42:24,270] [werkzeug] [INFO] 87  * Debugger pin code: 100-550-078
[2017-09-15 10:42:24,292] [werkzeug] [INFO] 87  * Running on http://0.0.0.0:9528/ (Press CTRL+C to quit)
[2017-09-15 10:43:05,048] [werkzeug] [INFO] 87 10.3.10.20 - - [15/Sep/2017 10:43:05] "GET /test/upload HTTP/1.1" 200 -
[2017-09-15 10:43:32,197] [bugHunter] [INFO] 17 文件接收并保存成功:E:\Learn\python\bugHunter\uploadFiles\5864ab29780c11505443412.png
[2017-09-15 10:43:32,197] [bugHunter] [INFO] 56 开始往jira往对应bug中插入附件,bugID:GXQ-29
[2017-09-15 10:43:32,201] [requests.packages.urllib3.connectionpool] [INFO] 213 Starting new HTTP connection (1): localhost
[2017-09-15 10:43:34,204] [root] [WARNING] 129 HTTPConnectionPool(host='localhost', port=2990): Max retries exceeded with url: /jira/rest/api/2/serverInfo (Caused by NewConnectionError('<requests.packages.urllib3.connection.HTTPConnection object at 0x000000000388ABE0>: Failed to establish a new connection: [Errno 10061] ',)) while doing GET http://localhost:2990/jira/rest/api/2/serverInfo [{u'headers': {'Accept-Encoding': 'gzip, deflate', u'Accept': u'application/json,*.*;q=0.9', 'User-Agent': 'python-requests/2.10.0', 'Connection': 'keep-alive', u'X-Atlassian-Token': u'no-check', u'Cache-Control': u'no-cache', u'Content-Type': u'application/json'}, 'params': None}]
[2017-09-15 10:43:34,206] [root] [WARNING] 86 Got ConnectionError [HTTPConnectionPool(host='localhost', port=2990): Max retries exceeded with url: /jira/rest/api/2/serverInfo (Caused by NewConnectionError('<requests.packages.urllib3.connection.HTTPConnection object at 0x000000000388ABE0>: Failed to establish a new connection: [Errno 10061] ',))] errno:None on GET http://localhost:2990/jira/rest/api/2/serverInfo
{'request': <PreparedRequest [GET]>, 'response': None}\{'request': <PreparedRequest [GET]>, 'response': None}
[2017-09-15 10:43:34,207] [root] [WARNING] 102 Got recoverable error from GET http://localhost:2990/jira/rest/api/2/serverInfo, will retry [1/3] in 3.50769646863s. Err: HTTPConnectionPool(host='localhost', port=2990): Max retries exceeded with url: /jira/rest/api/2/serverInfo (Caused by NewConnectionError('<requests.packages.urllib3.connection.HTTPConnection object at 0x000000000388ABE0>: Failed to establish a new connection: [Errno 10061] ',))
[2017-09-15 10:43:37,716] [requests.packages.urllib3.connectionpool] [INFO] 213 Starting new HTTP connection (2): localhost
[2017-09-15 10:43:39,720] [root] [WARNING] 129 HTTPConnectionPool(host='localhost', port=2990): Max retries exceeded with url: /jira/rest/api/2/serverInfo (Caused by NewConnectionError('<requests.packages.urllib3.connection.HTTPConnection object at 0x000000000388AE80>: Failed to establish a new connection: [Errno 10061] ',)) while doing GET http://localhost:2990/jira/rest/api/2/serverInfo [{u'headers': {'Accept-Encoding': 'gzip, deflate', u'Accept': u'application/json,*.*;q=0.9', 'User-Agent': 'python-requests/2.10.0', 'Connection': 'keep-alive', u'X-Atlassian-Token': u'no-check', u'Cache-Control': u'no-cache', u'Content-Type': u'application/json'}, 'params': None}]
[2017-09-15 10:43:39,720] [root] [WARNING] 86 Got ConnectionError [HTTPConnectionPool(host='localhost', port=2990): Max retries exceeded with url: /jira/rest/api/2/serverInfo (Caused by NewConnectionError('<requests.packages.urllib3.connection.HTTPConnection object at 0x000000000388AE80>: Failed to establish a new connection: [Errno 10061] ',))] errno:None on GET http://localhost:2990/jira/rest/api/2/serverInfo
{'request': <PreparedRequest [GET]>, 'response': None}\{'request': <PreparedRequest [GET]>, 'response': None}
[2017-09-15 10:43:39,721] [root] [WARNING] 102 Got recoverable error from GET http://localhost:2990/jira/rest/api/2/serverInfo, will retry [2/3] in 8.37476411975s. Err: HTTPConnectionPool(host='localhost', port=2990): Max retries exceeded with url: /jira/rest/api/2/serverInfo (Caused by NewConnectionError('<requests.packages.urllib3.connection.HTTPConnection object at 0x000000000388AE80>: Failed to establish a new connection: [Errno 10061] ',))
[2017-09-15 10:43:48,096] [requests.packages.urllib3.connectionpool] [INFO] 213 Starting new HTTP connection (3): localhost
[2017-09-15 10:43:50,099] [root] [WARNING] 129 HTTPConnectionPool(host='localhost', port=2990): Max retries exceeded with url: /jira/rest/api/2/serverInfo (Caused by NewConnectionError('<requests.packages.urllib3.connection.HTTPConnection object at 0x000000000388AF98>: Failed to establish a new connection: [Errno 10061] ',)) while doing GET http://localhost:2990/jira/rest/api/2/serverInfo [{u'headers': {'Accept-Encoding': 'gzip, deflate', u'Accept': u'application/json,*.*;q=0.9', 'User-Agent': 'python-requests/2.10.0', 'Connection': 'keep-alive', u'X-Atlassian-Token': u'no-check', u'Cache-Control': u'no-cache', u'Content-Type': u'application/json'}, 'params': None}]
[2017-09-15 10:43:50,101] [root] [WARNING] 86 Got ConnectionError [HTTPConnectionPool(host='localhost', port=2990): Max retries exceeded with url: /jira/rest/api/2/serverInfo (Caused by NewConnectionError('<requests.packages.urllib3.connection.HTTPConnection object at 0x000000000388AF98>: Failed to establish a new connection: [Errno 10061] ',))] errno:None on GET http://localhost:2990/jira/rest/api/2/serverInfo
{'request': <PreparedRequest [GET]>, 'response': None}\{'request': <PreparedRequest [GET]>, 'response': None}
[2017-09-15 10:43:50,101] [root] [WARNING] 102 Got recoverable error from GET http://localhost:2990/jira/rest/api/2/serverInfo, will retry [3/3] in 38.4074988856s. Err: HTTPConnectionPool(host='localhost', port=2990): Max retries exceeded with url: /jira/rest/api/2/serverInfo (Caused by NewConnectionError('<requests.packages.urllib3.connection.HTTPConnection object at 0x000000000388AF98>: Failed to establish a new connection: [Errno 10061] ',))
[2017-09-15 10:44:28,512] [requests.packages.urllib3.connectionpool] [INFO] 213 Starting new HTTP connection (4): localhost
[2017-09-15 10:44:30,516] [root] [WARNING] 129 HTTPConnectionPool(host='localhost', port=2990): Max retries exceeded with url: /jira/rest/api/2/serverInfo (Caused by NewConnectionError('<requests.packages.urllib3.connection.HTTPConnection object at 0x000000000388AEB8>: Failed to establish a new connection: [Errno 10061] ',)) while doing GET http://localhost:2990/jira/rest/api/2/serverInfo [{u'headers': {'Accept-Encoding': 'gzip, deflate', u'Accept': u'application/json,*.*;q=0.9', 'User-Agent': 'python-requests/2.10.0', 'Connection': 'keep-alive', u'X-Atlassian-Token': u'no-check', u'Cache-Control': u'no-cache', u'Content-Type': u'application/json'}, 'params': None}]
[2017-09-15 10:44:30,578] [werkzeug] [INFO] 87 10.3.10.20 - - [15/Sep/2017 10:44:30] "POST /bughunter/upload HTTP/1.1" 500 -
[2017-09-15 10:44:30,687] [werkzeug] [INFO] 87 10.3.10.20 - - [15/Sep/2017 10:44:30] "GET /bughunter/upload?__debugger__=yes&cmd=resource&f=style.css HTTP/1.1" 200 -
[2017-09-15 10:44:30,698] [werkzeug] [INFO] 87 10.3.10.20 - - [15/Sep/2017 10:44:30] "GET /bughunter/upload?__debugger__=yes&cmd=resource&f=jquery.js HTTP/1.1" 200 -
[2017-09-15 10:44:30,711] [werkzeug] [INFO] 87 10.3.10.20 - - [15/Sep/2017 10:44:30] "GET /bughunter/upload?__debugger__=yes&cmd=resource&f=debugger.js HTTP/1.1" 200 -
[2017-09-15 10:44:30,743] [werkzeug] [INFO] 87 10.3.10.20 - - [15/Sep/2017 10:44:30] "GET /bughunter/upload?__debugger__=yes&cmd=resource&f=ubuntu.ttf HTTP/1.1" 200 -
[2017-09-15 10:44:30,821] [werkzeug] [INFO] 87 10.3.10.20 - - [15/Sep/2017 10:44:30] "GET /bughunter/upload?__debugger__=yes&cmd=resource&f=console.png HTTP/1.1" 200 -
[2017-09-15 10:45:46,375] [werkzeug] [INFO] 87  * Detected change in 'E:\\Learn\\python\\bugHunter\\insertAttachment.py', reloading
[2017-09-15 10:45:46,423] [werkzeug] [INFO] 87  * Restarting with stat
[2017-09-15 10:45:46,648] [werkzeug] [WARNING] 87  * Debugger is active!
[2017-09-15 10:45:46,653] [werkzeug] [INFO] 87  * Debugger pin code: 100-550-078
[2017-09-15 10:45:46,661] [werkzeug] [INFO] 87  * Running on http://0.0.0.0:9528/ (Press CTRL+C to quit)
[2017-09-15 10:48:25,841] [werkzeug] [INFO] 87  * Restarting with stat
[2017-09-15 10:48:26,467] [werkzeug] [WARNING] 87  * Debugger is active!
[2017-09-15 10:48:26,470] [werkzeug] [INFO] 87  * Debugger pin code: 100-550-078
[2017-09-15 10:48:26,480] [werkzeug] [INFO] 87  * Running on http://0.0.0.0:9528/ (Press CTRL+C to quit)
[2017-09-15 10:48:30,108] [bugHunter] [INFO] 17 文件接收并保存成功:E:\Learn\python\bugHunter\uploadFiles\5864ab29780c11505443710.png
[2017-09-15 10:48:30,108] [bugHunter] [INFO] 56 开始往jira往对应bug中插入附件,bugID:GXQ-29
[2017-09-15 10:48:38,197] [requests.packages.urllib3.connectionpool] [INFO] 213 Starting new HTTP connection (1): localhost
[2017-09-15 10:48:40,200] [root] [WARNING] 129 HTTPConnectionPool(host='localhost', port=2990): Max retries exceeded with url: /jira/rest/api/2/serverInfo (Caused by NewConnectionError('<requests.packages.urllib3.connection.HTTPConnection object at 0x00000000045B0B00>: Failed to establish a new connection: [Errno 10061] ',)) while doing GET http://localhost:2990/jira/rest/api/2/serverInfo [{u'headers': {'Accept-Encoding': 'gzip, deflate', u'Accept': u'application/json,*.*;q=0.9', 'User-Agent': 'python-requests/2.10.0', 'Connection': 'keep-alive', u'X-Atlassian-Token': u'no-check', u'Cache-Control': u'no-cache', u'Content-Type': u'application/json'}, 'params': None}]
[2017-09-15 10:48:40,200] [root] [WARNING] 86 Got ConnectionError [HTTPConnectionPool(host='localhost', port=2990): Max retries exceeded with url: /jira/rest/api/2/serverInfo (Caused by NewConnectionError('<requests.packages.urllib3.connection.HTTPConnection object at 0x00000000045B0B00>: Failed to establish a new connection: [Errno 10061] ',))] errno:None on GET http://localhost:2990/jira/rest/api/2/serverInfo
{'request': <PreparedRequest [GET]>, 'response': None}\{'request': <PreparedRequest [GET]>, 'response': None}
[2017-09-15 10:48:40,200] [root] [WARNING] 102 Got recoverable error from GET http://localhost:2990/jira/rest/api/2/serverInfo, will retry [1/3] in 17.471670611s. Err: HTTPConnectionPool(host='localhost', port=2990): Max retries exceeded with url: /jira/rest/api/2/serverInfo (Caused by NewConnectionError('<requests.packages.urllib3.connection.HTTPConnection object at 0x00000000045B0B00>: Failed to establish a new connection: [Errno 10061] ',))
[2017-09-15 10:48:57,677] [requests.packages.urllib3.connectionpool] [INFO] 213 Starting new HTTP connection (2): localhost
[2017-09-15 10:48:59,683] [root] [WARNING] 129 HTTPConnectionPool(host='localhost', port=2990): Max retries exceeded with url: /jira/rest/api/2/serverInfo (Caused by NewConnectionError('<requests.packages.urllib3.connection.HTTPConnection object at 0x00000000045B0DA0>: Failed to establish a new connection: [Errno 10061] ',)) while doing GET http://localhost:2990/jira/rest/api/2/serverInfo [{u'headers': {'Accept-Encoding': 'gzip, deflate', u'Accept': u'application/json,*.*;q=0.9', 'User-Agent': 'python-requests/2.10.0', 'Connection': 'keep-alive', u'X-Atlassian-Token': u'no-check', u'Cache-Control': u'no-cache', u'Content-Type': u'application/json'}, 'params': None}]
[2017-09-15 10:48:59,684] [root] [WARNING] 86 Got ConnectionError [HTTPConnectionPool(host='localhost', port=2990): Max retries exceeded with url: /jira/rest/api/2/serverInfo (Caused by NewConnectionError('<requests.packages.urllib3.connection.HTTPConnection object at 0x00000000045B0DA0>: Failed to establish a new connection: [Errno 10061] ',))] errno:None on GET http://localhost:2990/jira/rest/api/2/serverInfo
{'request': <PreparedRequest [GET]>, 'response': None}\{'request': <PreparedRequest [GET]>, 'response': None}
[2017-09-15 10:48:59,684] [root] [WARNING] 102 Got recoverable error from GET http://localhost:2990/jira/rest/api/2/serverInfo, will retry [2/3] in 34.0602975151s. Err: HTTPConnectionPool(host='localhost', port=2990): Max retries exceeded with url: /jira/rest/api/2/serverInfo (Caused by NewConnectionError('<requests.packages.urllib3.connection.HTTPConnection object at 0x00000000045B0DA0>: Failed to establish a new connection: [Errno 10061] ',))
[2017-09-15 10:49:43,253] [werkzeug] [INFO] 87  * Restarting with stat
[2017-09-15 10:49:43,835] [werkzeug] [WARNING] 87  * Debugger is active!
[2017-09-15 10:49:43,838] [werkzeug] [INFO] 87  * Debugger pin code: 100-550-078
[2017-09-15 10:49:43,848] [werkzeug] [INFO] 87  * Running on http://0.0.0.0:9528/ (Press CTRL+C to quit)
[2017-09-15 10:49:48,154] [bugHunter] [INFO] 17 文件接收并保存成功:E:\Learn\python\bugHunter\uploadFiles\5864ab29780c11505443788.png
[2017-09-15 10:49:48,154] [bugHunter] [INFO] 56 开始往jira往对应bug中插入附件,bugID:GXQ-29
[2017-09-15 10:49:48,164] [requests.packages.urllib3.connectionpool] [INFO] 213 Starting new HTTP connection (1): localhost
[2017-09-15 10:49:50,193] [root] [WARNING] 129 HTTPConnectionPool(host='localhost', port=2990): Max retries exceeded with url: /jira/rest/api/2/serverInfo (Caused by NewConnectionError('<requests.packages.urllib3.connection.HTTPConnection object at 0x000000000462BA90>: Failed to establish a new connection: [Errno 10061] ',)) while doing GET http://localhost:2990/jira/rest/api/2/serverInfo [{u'headers': {'Accept-Encoding': 'gzip, deflate', u'Accept': u'application/json,*.*;q=0.9', 'User-Agent': 'python-requests/2.10.0', 'Connection': 'keep-alive', u'X-Atlassian-Token': u'no-check', u'Cache-Control': u'no-cache', u'Content-Type': u'application/json'}, 'params': None}]
[2017-09-15 10:49:50,194] [root] [WARNING] 86 Got ConnectionError [HTTPConnectionPool(host='localhost', port=2990): Max retries exceeded with url: /jira/rest/api/2/serverInfo (Caused by NewConnectionError('<requests.packages.urllib3.connection.HTTPConnection object at 0x000000000462BA90>: Failed to establish a new connection: [Errno 10061] ',))] errno:None on GET http://localhost:2990/jira/rest/api/2/serverInfo
{'request': <PreparedRequest [GET]>, 'response': None}\{'request': <PreparedRequest [GET]>, 'response': None}
[2017-09-15 10:49:50,194] [root] [WARNING] 102 Got recoverable error from GET http://localhost:2990/jira/rest/api/2/serverInfo, will retry [1/3] in 4.65195013061s. Err: HTTPConnectionPool(host='localhost', port=2990): Max retries exceeded with url: /jira/rest/api/2/serverInfo (Caused by NewConnectionError('<requests.packages.urllib3.connection.HTTPConnection object at 0x000000000462BA90>: Failed to establish a new connection: [Errno 10061] ',))
[2017-09-15 10:49:54,849] [requests.packages.urllib3.connectionpool] [INFO] 213 Starting new HTTP connection (2): localhost
[2017-09-15 10:49:56,852] [root] [WARNING] 129 HTTPConnectionPool(host='localhost', port=2990): Max retries exceeded with url: /jira/rest/api/2/serverInfo (Caused by NewConnectionError('<requests.packages.urllib3.connection.HTTPConnection object at 0x000000000462BD30>: Failed to establish a new connection: [Errno 10061] ',)) while doing GET http://localhost:2990/jira/rest/api/2/serverInfo [{u'headers': {'Accept-Encoding': 'gzip, deflate', u'Accept': u'application/json,*.*;q=0.9', 'User-Agent': 'python-requests/2.10.0', 'Connection': 'keep-alive', u'X-Atlassian-Token': u'no-check', u'Cache-Control': u'no-cache', u'Content-Type': u'application/json'}, 'params': None}]
[2017-09-15 10:49:56,852] [root] [WARNING] 86 Got ConnectionError [HTTPConnectionPool(host='localhost', port=2990): Max retries exceeded with url: /jira/rest/api/2/serverInfo (Caused by NewConnectionError('<requests.packages.urllib3.connection.HTTPConnection object at 0x000000000462BD30>: Failed to establish a new connection: [Errno 10061] ',))] errno:None on GET http://localhost:2990/jira/rest/api/2/serverInfo
{'request': <PreparedRequest [GET]>, 'response': None}\{'request': <PreparedRequest [GET]>, 'response': None}
[2017-09-15 10:49:56,852] [root] [WARNING] 102 Got recoverable error from GET http://localhost:2990/jira/rest/api/2/serverInfo, will retry [2/3] in 22.7118307885s. Err: HTTPConnectionPool(host='localhost', port=2990): Max retries exceeded with url: /jira/rest/api/2/serverInfo (Caused by NewConnectionError('<requests.packages.urllib3.connection.HTTPConnection object at 0x000000000462BD30>: Failed to establish a new connection: [Errno 10061] ',))
[2017-09-15 10:50:19,568] [requests.packages.urllib3.connectionpool] [INFO] 213 Starting new HTTP connection (3): localhost
[2017-09-15 10:50:21,569] [root] [WARNING] 129 HTTPConnectionPool(host='localhost', port=2990): Max retries exceeded with url: /jira/rest/api/2/serverInfo (Caused by NewConnectionError('<requests.packages.urllib3.connection.HTTPConnection object at 0x000000000462B9B0>: Failed to establish a new connection: [Errno 10061] ',)) while doing GET http://localhost:2990/jira/rest/api/2/serverInfo [{u'headers': {'Accept-Encoding': 'gzip, deflate', u'Accept': u'application/json,*.*;q=0.9', 'User-Agent': 'python-requests/2.10.0', 'Connection': 'keep-alive', u'X-Atlassian-Token': u'no-check', u'Cache-Control': u'no-cache', u'Content-Type': u'application/json'}, 'params': None}]
[2017-09-15 10:50:21,569] [root] [WARNING] 86 Got ConnectionError [HTTPConnectionPool(host='localhost', port=2990): Max retries exceeded with url: /jira/rest/api/2/serverInfo (Caused by NewConnectionError('<requests.packages.urllib3.connection.HTTPConnection object at 0x000000000462B9B0>: Failed to establish a new connection: [Errno 10061] ',))] errno:None on GET http://localhost:2990/jira/rest/api/2/serverInfo
{'request': <PreparedRequest [GET]>, 'response': None}\{'request': <PreparedRequest [GET]>, 'response': None}
[2017-09-15 10:50:21,569] [root] [WARNING] 102 Got recoverable error from GET http://localhost:2990/jira/rest/api/2/serverInfo, will retry [3/3] in 25.8623833058s. Err: HTTPConnectionPool(host='localhost', port=2990): Max retries exceeded with url: /jira/rest/api/2/serverInfo (Caused by NewConnectionError('<requests.packages.urllib3.connection.HTTPConnection object at 0x000000000462B9B0>: Failed to establish a new connection: [Errno 10061] ',))
[2017-09-15 10:50:59,674] [werkzeug] [INFO] 87  * Restarting with stat
[2017-09-15 10:51:00,256] [werkzeug] [WARNING] 87  * Debugger is active!
[2017-09-15 10:51:00,259] [werkzeug] [INFO] 87  * Debugger pin code: 100-550-078
[2017-09-15 10:51:00,266] [werkzeug] [INFO] 87  * Running on http://0.0.0.0:9528/ (Press CTRL+C to quit)
[2017-09-15 10:51:02,249] [bugHunter] [INFO] 17 文件接收并保存成功:E:\Learn\python\bugHunter\uploadFiles\5864ab29780c11505443862.png
[2017-09-15 10:51:02,250] [bugHunter] [INFO] 56 开始往jira往对应bug中插入附件,bugID:GXQ-29
[2017-09-15 10:51:02,257] [requests.packages.urllib3.connectionpool] [INFO] 213 Starting new HTTP connection (1): localhost
[2017-09-15 10:51:04,256] [root] [WARNING] 129 HTTPConnectionPool(host='localhost', port=2990): Max retries exceeded with url: /jira/rest/api/2/serverInfo (Caused by NewConnectionError('<requests.packages.urllib3.connection.HTTPConnection object at 0x00000000044C88D0>: Failed to establish a new connection: [Errno 10061] ',)) while doing GET http://localhost:2990/jira/rest/api/2/serverInfo [{u'headers': {'Accept-Encoding': 'gzip, deflate', u'Accept': u'application/json,*.*;q=0.9', 'User-Agent': 'python-requests/2.10.0', 'Connection': 'keep-alive', u'X-Atlassian-Token': u'no-check', u'Cache-Control': u'no-cache', u'Content-Type': u'application/json'}, 'params': None}]
[2017-09-15 10:51:04,257] [root] [WARNING] 86 Got ConnectionError [HTTPConnectionPool(host='localhost', port=2990): Max retries exceeded with url: /jira/rest/api/2/serverInfo (Caused by NewConnectionError('<requests.packages.urllib3.connection.HTTPConnection object at 0x00000000044C88D0>: Failed to establish a new connection: [Errno 10061] ',))] errno:None on GET http://localhost:2990/jira/rest/api/2/serverInfo
{'request': <PreparedRequest [GET]>, 'response': None}\{'request': <PreparedRequest [GET]>, 'response': None}
[2017-09-15 10:51:04,257] [root] [WARNING] 102 Got recoverable error from GET http://localhost:2990/jira/rest/api/2/serverInfo, will retry [1/3] in 12.5950402546s. Err: HTTPConnectionPool(host='localhost', port=2990): Max retries exceeded with url: /jira/rest/api/2/serverInfo (Caused by NewConnectionError('<requests.packages.urllib3.connection.HTTPConnection object at 0x00000000044C88D0>: Failed to establish a new connection: [Errno 10061] ',))
[2017-09-15 10:51:21,351] [werkzeug] [INFO] 87  * Restarting with stat
[2017-09-15 10:51:21,976] [werkzeug] [WARNING] 87  * Debugger is active!
[2017-09-15 10:51:21,979] [werkzeug] [INFO] 87  * Debugger pin code: 100-550-078
[2017-09-15 10:51:21,983] [werkzeug] [INFO] 87  * Running on http://0.0.0.0:9528/ (Press CTRL+C to quit)
[2017-09-15 10:51:32,280] [bugHunter] [INFO] 17 文件接收并保存成功:E:\Learn\python\bugHunter\uploadFiles\5864ab29780c11505443892.png
[2017-09-15 10:51:32,280] [bugHunter] [INFO] 56 开始往jira往对应bug中插入附件,bugID:GXQ-29
[2017-09-15 10:51:39,279] [requests.packages.urllib3.connectionpool] [INFO] 213 Starting new HTTP connection (1): localhost
[2017-09-15 10:51:41,282] [root] [WARNING] 129 HTTPConnectionPool(host='localhost', port=2990): Max retries exceeded with url: /jira/rest/api/2/serverInfo (Caused by NewConnectionError('<requests.packages.urllib3.connection.HTTPConnection object at 0x0000000004635B38>: Failed to establish a new connection: [Errno 10061] ',)) while doing GET http://localhost:2990/jira/rest/api/2/serverInfo [{u'headers': {'Accept-Encoding': 'gzip, deflate', u'Accept': u'application/json,*.*;q=0.9', 'User-Agent': 'python-requests/2.10.0', 'Connection': 'keep-alive', u'X-Atlassian-Token': u'no-check', u'Cache-Control': u'no-cache', u'Content-Type': u'application/json'}, 'params': None}]
[2017-09-15 10:51:41,283] [root] [WARNING] 86 Got ConnectionError [HTTPConnectionPool(host='localhost', port=2990): Max retries exceeded with url: /jira/rest/api/2/serverInfo (Caused by NewConnectionError('<requests.packages.urllib3.connection.HTTPConnection object at 0x0000000004635B38>: Failed to establish a new connection: [Errno 10061] ',))] errno:None on GET http://localhost:2990/jira/rest/api/2/serverInfo
{'request': <PreparedRequest [GET]>, 'response': None}\{'request': <PreparedRequest [GET]>, 'response': None}
[2017-09-15 10:51:41,283] [root] [WARNING] 102 Got recoverable error from GET http://localhost:2990/jira/rest/api/2/serverInfo, will retry [1/3] in 14.2924881264s. Err: HTTPConnectionPool(host='localhost', port=2990): Max retries exceeded with url: /jira/rest/api/2/serverInfo (Caused by NewConnectionError('<requests.packages.urllib3.connection.HTTPConnection object at 0x0000000004635B38>: Failed to establish a new connection: [Errno 10061] ',))
[2017-09-15 10:51:55,579] [requests.packages.urllib3.connectionpool] [INFO] 213 Starting new HTTP connection (2): localhost
[2017-09-15 10:54:46,177] [werkzeug] [INFO] 87  * Restarting with stat
[2017-09-15 10:54:46,417] [werkzeug] [WARNING] 87  * Debugger is active!
[2017-09-15 10:54:46,420] [werkzeug] [INFO] 87  * Debugger pin code: 100-550-078
[2017-09-15 10:54:46,427] [werkzeug] [INFO] 87  * Running on http://0.0.0.0:9528/ (Press CTRL+C to quit)
[2017-09-15 10:54:53,357] [bugHunter] [INFO] 17 文件接收并保存成功:E:\Learn\python\bugHunter\uploadFiles\5864ab29780c11505444093.png
[2017-09-15 10:54:53,357] [bugHunter] [INFO] 56 开始往jira往对应bug中插入附件,bugID:GXQ-29
[2017-09-15 10:54:53,362] [requests.packages.urllib3.connectionpool] [INFO] 213 Starting new HTTP connection (1): localhost
[2017-09-15 10:54:55,365] [root] [WARNING] 129 HTTPConnectionPool(host='localhost', port=2990): Max retries exceeded with url: /jira/rest/api/2/serverInfo (Caused by NewConnectionError('<requests.packages.urllib3.connection.HTTPConnection object at 0x0000000003798AC8>: Failed to establish a new connection: [Errno 10061] ',)) while doing GET http://localhost:2990/jira/rest/api/2/serverInfo [{u'headers': {'Accept-Encoding': 'gzip, deflate', u'Accept': u'application/json,*.*;q=0.9', 'User-Agent': 'python-requests/2.10.0', 'Connection': 'keep-alive', u'X-Atlassian-Token': u'no-check', u'Cache-Control': u'no-cache', u'Content-Type': u'application/json'}, 'params': None}]
[2017-09-15 10:54:55,367] [root] [WARNING] 86 Got ConnectionError [HTTPConnectionPool(host='localhost', port=2990): Max retries exceeded with url: /jira/rest/api/2/serverInfo (Caused by NewConnectionError('<requests.packages.urllib3.connection.HTTPConnection object at 0x0000000003798AC8>: Failed to establish a new connection: [Errno 10061] ',))] errno:None on GET http://localhost:2990/jira/rest/api/2/serverInfo
{'request': <PreparedRequest [GET]>, 'response': None}\{'request': <PreparedRequest [GET]>, 'response': None}
[2017-09-15 10:54:55,367] [root] [WARNING] 102 Got recoverable error from GET http://localhost:2990/jira/rest/api/2/serverInfo, will retry [1/3] in 7.00876296481s. Err: HTTPConnectionPool(host='localhost', port=2990): Max retries exceeded with url: /jira/rest/api/2/serverInfo (Caused by NewConnectionError('<requests.packages.urllib3.connection.HTTPConnection object at 0x0000000003798AC8>: Failed to establish a new connection: [Errno 10061] ',))
[2017-09-15 10:55:02,377] [requests.packages.urllib3.connectionpool] [INFO] 213 Starting new HTTP connection (2): localhost
[2017-09-15 10:55:04,397] [root] [WARNING] 129 HTTPConnectionPool(host='localhost', port=2990): Max retries exceeded with url: /jira/rest/api/2/serverInfo (Caused by NewConnectionError('<requests.packages.urllib3.connection.HTTPConnection object at 0x0000000003798D68>: Failed to establish a new connection: [Errno 10061] ',)) while doing GET http://localhost:2990/jira/rest/api/2/serverInfo [{u'headers': {'Accept-Encoding': 'gzip, deflate', u'Accept': u'application/json,*.*;q=0.9', 'User-Agent': 'python-requests/2.10.0', 'Connection': 'keep-alive', u'X-Atlassian-Token': u'no-check', u'Cache-Control': u'no-cache', u'Content-Type': u'application/json'}, 'params': None}]
[2017-09-15 10:55:04,397] [root] [WARNING] 86 Got ConnectionError [HTTPConnectionPool(host='localhost', port=2990): Max retries exceeded with url: /jira/rest/api/2/serverInfo (Caused by NewConnectionError('<requests.packages.urllib3.connection.HTTPConnection object at 0x0000000003798D68>: Failed to establish a new connection: [Errno 10061] ',))] errno:None on GET http://localhost:2990/jira/rest/api/2/serverInfo
{'request': <PreparedRequest [GET]>, 'response': None}\{'request': <PreparedRequest [GET]>, 'response': None}
[2017-09-15 10:55:04,398] [root] [WARNING] 102 Got recoverable error from GET http://localhost:2990/jira/rest/api/2/serverInfo, will retry [2/3] in 31.506131888s. Err: HTTPConnectionPool(host='localhost', port=2990): Max retries exceeded with url: /jira/rest/api/2/serverInfo (Caused by NewConnectionError('<requests.packages.urllib3.connection.HTTPConnection object at 0x0000000003798D68>: Failed to establish a new connection: [Errno 10061] ',))
[2017-09-15 10:55:27,096] [werkzeug] [INFO] 87  * Restarting with stat
[2017-09-15 10:55:27,326] [werkzeug] [WARNING] 87  * Debugger is active!
[2017-09-15 10:55:27,329] [werkzeug] [INFO] 87  * Debugger pin code: 100-550-078
[2017-09-15 10:55:27,341] [werkzeug] [INFO] 87  * Running on http://0.0.0.0:9528/ (Press CTRL+C to quit)
[2017-09-15 10:55:30,040] [bugHunter] [INFO] 17 文件接收并保存成功:E:\Learn\python\bugHunter\uploadFiles\5864ab29780c11505444130.png
[2017-09-15 10:55:30,040] [bugHunter] [INFO] 56 开始往jira往对应bug中插入附件,bugID:GXQ-29
[2017-09-15 10:55:30,053] [requests.packages.urllib3.connectionpool] [INFO] 213 Starting new HTTP connection (1): localhost
[2017-09-15 10:55:32,059] [root] [WARNING] 129 HTTPConnectionPool(host='localhost', port=2990): Max retries exceeded with url: /jira/rest/api/2/serverInfo (Caused by NewConnectionError('<requests.packages.urllib3.connection.HTTPConnection object at 0x0000000003803AC8>: Failed to establish a new connection: [Errno 10061] ',)) while doing GET http://localhost:2990/jira/rest/api/2/serverInfo [{u'headers': {'Accept-Encoding': 'gzip, deflate', u'Accept': u'application/json,*.*;q=0.9', 'User-Agent': 'python-requests/2.10.0', 'Connection': 'keep-alive', u'X-Atlassian-Token': u'no-check', u'Cache-Control': u'no-cache', u'Content-Type': u'application/json'}, 'params': None}]
[2017-09-15 10:55:32,059] [root] [WARNING] 86 Got ConnectionError [HTTPConnectionPool(host='localhost', port=2990): Max retries exceeded with url: /jira/rest/api/2/serverInfo (Caused by NewConnectionError('<requests.packages.urllib3.connection.HTTPConnection object at 0x0000000003803AC8>: Failed to establish a new connection: [Errno 10061] ',))] errno:None on GET http://localhost:2990/jira/rest/api/2/serverInfo
{'request': <PreparedRequest [GET]>, 'response': None}\{'request': <PreparedRequest [GET]>, 'response': None}
[2017-09-15 10:55:32,059] [root] [WARNING] 102 Got recoverable error from GET http://localhost:2990/jira/rest/api/2/serverInfo, will retry [1/3] in 16.6785080989s. Err: HTTPConnectionPool(host='localhost', port=2990): Max retries exceeded with url: /jira/rest/api/2/serverInfo (Caused by NewConnectionError('<requests.packages.urllib3.connection.HTTPConnection object at 0x0000000003803AC8>: Failed to establish a new connection: [Errno 10061] ',))
[2017-09-15 10:55:48,740] [requests.packages.urllib3.connectionpool] [INFO] 213 Starting new HTTP connection (2): localhost
[2017-09-15 10:55:50,739] [root] [WARNING] 129 HTTPConnectionPool(host='localhost', port=2990): Max retries exceeded with url: /jira/rest/api/2/serverInfo (Caused by NewConnectionError('<requests.packages.urllib3.connection.HTTPConnection object at 0x0000000003803D68>: Failed to establish a new connection: [Errno 10061] ',)) while doing GET http://localhost:2990/jira/rest/api/2/serverInfo [{u'headers': {'Accept-Encoding': 'gzip, deflate', u'Accept': u'application/json,*.*;q=0.9', 'User-Agent': 'python-requests/2.10.0', 'Connection': 'keep-alive', u'X-Atlassian-Token': u'no-check', u'Cache-Control': u'no-cache', u'Content-Type': u'application/json'}, 'params': None}]
[2017-09-15 10:55:50,739] [root] [WARNING] 86 Got ConnectionError [HTTPConnectionPool(host='localhost', port=2990): Max retries exceeded with url: /jira/rest/api/2/serverInfo (Caused by NewConnectionError('<requests.packages.urllib3.connection.HTTPConnection object at 0x0000000003803D68>: Failed to establish a new connection: [Errno 10061] ',))] errno:None on GET http://localhost:2990/jira/rest/api/2/serverInfo
{'request': <PreparedRequest [GET]>, 'response': None}\{'request': <PreparedRequest [GET]>, 'response': None}
[2017-09-15 10:55:50,739] [root] [WARNING] 102 Got recoverable error from GET http://localhost:2990/jira/rest/api/2/serverInfo, will retry [2/3] in 26.1487571276s. Err: HTTPConnectionPool(host='localhost', port=2990): Max retries exceeded with url: /jira/rest/api/2/serverInfo (Caused by NewConnectionError('<requests.packages.urllib3.connection.HTTPConnection object at 0x0000000003803D68>: Failed to establish a new connection: [Errno 10061] ',))
[2017-09-15 10:56:16,890] [requests.packages.urllib3.connectionpool] [INFO] 213 Starting new HTTP connection (3): localhost
[2017-09-15 10:56:18,891] [root] [WARNING] 129 HTTPConnectionPool(host='localhost', port=2990): Max retries exceeded with url: /jira/rest/api/2/serverInfo (Caused by NewConnectionError('<requests.packages.urllib3.connection.HTTPConnection object at 0x0000000003803E80>: Failed to establish a new connection: [Errno 10061] ',)) while doing GET http://localhost:2990/jira/rest/api/2/serverInfo [{u'headers': {'Accept-Encoding': 'gzip, deflate', u'Accept': u'application/json,*.*;q=0.9', 'User-Agent': 'python-requests/2.10.0', 'Connection': 'keep-alive', u'X-Atlassian-Token': u'no-check', u'Cache-Control': u'no-cache', u'Content-Type': u'application/json'}, 'params': None}]
[2017-09-15 10:56:18,891] [root] [WARNING] 86 Got ConnectionError [HTTPConnectionPool(host='localhost', port=2990): Max retries exceeded with url: /jira/rest/api/2/serverInfo (Caused by NewConnectionError('<requests.packages.urllib3.connection.HTTPConnection object at 0x0000000003803E80>: Failed to establish a new connection: [Errno 10061] ',))] errno:None on GET http://localhost:2990/jira/rest/api/2/serverInfo
{'request': <PreparedRequest [GET]>, 'response': None}\{'request': <PreparedRequest [GET]>, 'response': None}
[2017-09-15 10:56:18,892] [root] [WARNING] 102 Got recoverable error from GET http://localhost:2990/jira/rest/api/2/serverInfo, will retry [3/3] in 10.6048137715s. Err: HTTPConnectionPool(host='localhost', port=2990): Max retries exceeded with url: /jira/rest/api/2/serverInfo (Caused by NewConnectionError('<requests.packages.urllib3.connection.HTTPConnection object at 0x0000000003803E80>: Failed to establish a new connection: [Errno 10061] ',))
[2017-09-15 10:56:29,500] [requests.packages.urllib3.connectionpool] [INFO] 213 Starting new HTTP connection (4): localhost
[2017-09-15 10:56:31,500] [root] [WARNING] 129 HTTPConnectionPool(host='localhost', port=2990): Max retries exceeded with url: /jira/rest/api/2/serverInfo (Caused by NewConnectionError('<requests.packages.urllib3.connection.HTTPConnection object at 0x0000000003803F28>: Failed to establish a new connection: [Errno 10061] ',)) while doing GET http://localhost:2990/jira/rest/api/2/serverInfo [{u'headers': {'Accept-Encoding': 'gzip, deflate', u'Accept': u'application/json,*.*;q=0.9', 'User-Agent': 'python-requests/2.10.0', 'Connection': 'keep-alive', u'X-Atlassian-Token': u'no-check', u'Cache-Control': u'no-cache', u'Content-Type': u'application/json'}, 'params': None}]
[2017-09-15 10:56:31,529] [werkzeug] [INFO] 87 10.3.10.20 - - [15/Sep/2017 10:56:31] "POST /bughunter/upload HTTP/1.1" 500 -
[2017-09-15 10:56:31,644] [werkzeug] [INFO] 87 10.3.10.20 - - [15/Sep/2017 10:56:31] "GET /bughunter/upload?__debugger__=yes&cmd=resource&f=style.css HTTP/1.1" 200 -
[2017-09-15 10:56:31,647] [werkzeug] [INFO] 87 10.3.10.20 - - [15/Sep/2017 10:56:31] "GET /bughunter/upload?__debugger__=yes&cmd=resource&f=jquery.js HTTP/1.1" 200 -
[2017-09-15 10:56:31,651] [werkzeug] [INFO] 87 10.3.10.20 - - [15/Sep/2017 10:56:31] "GET /bughunter/upload?__debugger__=yes&cmd=resource&f=debugger.js HTTP/1.1" 200 -
[2017-09-15 10:56:31,676] [werkzeug] [INFO] 87 10.3.10.20 - - [15/Sep/2017 10:56:31] "GET /bughunter/upload?__debugger__=yes&cmd=resource&f=ubuntu.ttf HTTP/1.1" 200 -
[2017-09-15 10:56:31,717] [werkzeug] [INFO] 87 10.3.10.20 - - [15/Sep/2017 10:56:31] "GET /bughunter/upload?__debugger__=yes&cmd=resource&f=console.png HTTP/1.1" 200 -
[2017-09-15 10:56:36,762] [werkzeug] [INFO] 87  * Restarting with stat
[2017-09-15 10:56:37,132] [werkzeug] [WARNING] 87  * Debugger is active!
[2017-09-15 10:56:37,137] [werkzeug] [INFO] 87  * Debugger pin code: 100-550-078
[2017-09-15 10:56:37,142] [werkzeug] [INFO] 87  * Running on http://0.0.0.0:9528/ (Press CTRL+C to quit)
[2017-09-15 10:56:44,338] [bugHunter] [INFO] 17 文件接收并保存成功:E:\Learn\python\bugHunter\uploadFiles\5864ab29780c11505444204.png
[2017-09-15 10:56:44,338] [bugHunter] [INFO] 56 开始往jira往对应bug中插入附件,bugID:GXQ-29
[2017-09-15 10:56:44,344] [requests.packages.urllib3.connectionpool] [INFO] 213 Starting new HTTP connection (1): localhost
[2017-09-15 10:56:46,345] [root] [WARNING] 129 HTTPConnectionPool(host='localhost', port=2990): Max retries exceeded with url: /jira/rest/api/2/serverInfo (Caused by NewConnectionError('<requests.packages.urllib3.connection.HTTPConnection object at 0x0000000003795AC8>: Failed to establish a new connection: [Errno 10061] ',)) while doing GET http://localhost:2990/jira/rest/api/2/serverInfo [{u'headers': {'Accept-Encoding': 'gzip, deflate', u'Accept': u'application/json,*.*;q=0.9', 'User-Agent': 'python-requests/2.10.0', 'Connection': 'keep-alive', u'X-Atlassian-Token': u'no-check', u'Cache-Control': u'no-cache', u'Content-Type': u'application/json'}, 'params': None}]
[2017-09-15 10:56:46,345] [root] [WARNING] 86 Got ConnectionError [HTTPConnectionPool(host='localhost', port=2990): Max retries exceeded with url: /jira/rest/api/2/serverInfo (Caused by NewConnectionError('<requests.packages.urllib3.connection.HTTPConnection object at 0x0000000003795AC8>: Failed to establish a new connection: [Errno 10061] ',))] errno:None on GET http://localhost:2990/jira/rest/api/2/serverInfo
{'request': <PreparedRequest [GET]>, 'response': None}\{'request': <PreparedRequest [GET]>, 'response': None}
[2017-09-15 10:56:46,345] [root] [WARNING] 102 Got recoverable error from GET http://localhost:2990/jira/rest/api/2/serverInfo, will retry [1/3] in 4.2021962442s. Err: HTTPConnectionPool(host='localhost', port=2990): Max retries exceeded with url: /jira/rest/api/2/serverInfo (Caused by NewConnectionError('<requests.packages.urllib3.connection.HTTPConnection object at 0x0000000003795AC8>: Failed to establish a new connection: [Errno 10061] ',))
[2017-09-15 10:56:50,549] [requests.packages.urllib3.connectionpool] [INFO] 213 Starting new HTTP connection (2): localhost
[2017-09-15 10:56:52,551] [root] [WARNING] 129 HTTPConnectionPool(host='localhost', port=2990): Max retries exceeded with url: /jira/rest/api/2/serverInfo (Caused by NewConnectionError('<requests.packages.urllib3.connection.HTTPConnection object at 0x0000000003795D68>: Failed to establish a new connection: [Errno 10061] ',)) while doing GET http://localhost:2990/jira/rest/api/2/serverInfo [{u'headers': {'Accept-Encoding': 'gzip, deflate', u'Accept': u'application/json,*.*;q=0.9', 'User-Agent': 'python-requests/2.10.0', 'Connection': 'keep-alive', u'X-Atlassian-Token': u'no-check', u'Cache-Control': u'no-cache', u'Content-Type': u'application/json'}, 'params': None}]
[2017-09-15 10:56:52,551] [root] [WARNING] 86 Got ConnectionError [HTTPConnectionPool(host='localhost', port=2990): Max retries exceeded with url: /jira/rest/api/2/serverInfo (Caused by NewConnectionError('<requests.packages.urllib3.connection.HTTPConnection object at 0x0000000003795D68>: Failed to establish a new connection: [Errno 10061] ',))] errno:None on GET http://localhost:2990/jira/rest/api/2/serverInfo
{'request': <PreparedRequest [GET]>, 'response': None}\{'request': <PreparedRequest [GET]>, 'response': None}
[2017-09-15 10:56:52,551] [root] [WARNING] 102 Got recoverable error from GET http://localhost:2990/jira/rest/api/2/serverInfo, will retry [2/3] in 20.1211348799s. Err: HTTPConnectionPool(host='localhost', port=2990): Max retries exceeded with url: /jira/rest/api/2/serverInfo (Caused by NewConnectionError('<requests.packages.urllib3.connection.HTTPConnection object at 0x0000000003795D68>: Failed to establish a new connection: [Errno 10061] ',))
[2017-09-15 10:57:12,674] [requests.packages.urllib3.connectionpool] [INFO] 213 Starting new HTTP connection (3): localhost
[2017-09-15 10:57:14,676] [root] [WARNING] 129 HTTPConnectionPool(host='localhost', port=2990): Max retries exceeded with url: /jira/rest/api/2/serverInfo (Caused by NewConnectionError('<requests.packages.urllib3.connection.HTTPConnection object at 0x0000000003795E80>: Failed to establish a new connection: [Errno 10061] ',)) while doing GET http://localhost:2990/jira/rest/api/2/serverInfo [{u'headers': {'Accept-Encoding': 'gzip, deflate', u'Accept': u'application/json,*.*;q=0.9', 'User-Agent': 'python-requests/2.10.0', 'Connection': 'keep-alive', u'X-Atlassian-Token': u'no-check', u'Cache-Control': u'no-cache', u'Content-Type': u'application/json'}, 'params': None}]
[2017-09-15 10:57:14,676] [root] [WARNING] 86 Got ConnectionError [HTTPConnectionPool(host='localhost', port=2990): Max retries exceeded with url: /jira/rest/api/2/serverInfo (Caused by NewConnectionError('<requests.packages.urllib3.connection.HTTPConnection object at 0x0000000003795E80>: Failed to establish a new connection: [Errno 10061] ',))] errno:None on GET http://localhost:2990/jira/rest/api/2/serverInfo
{'request': <PreparedRequest [GET]>, 'response': None}\{'request': <PreparedRequest [GET]>, 'response': None}
[2017-09-15 10:57:14,676] [root] [WARNING] 102 Got recoverable error from GET http://localhost:2990/jira/rest/api/2/serverInfo, will retry [3/3] in 50.5394091702s. Err: HTTPConnectionPool(host='localhost', port=2990): Max retries exceeded with url: /jira/rest/api/2/serverInfo (Caused by NewConnectionError('<requests.packages.urllib3.connection.HTTPConnection object at 0x0000000003795E80>: Failed to establish a new connection: [Errno 10061] ',))
[2017-09-15 10:58:05,220] [requests.packages.urllib3.connectionpool] [INFO] 213 Starting new HTTP connection (4): localhost
[2017-09-15 10:58:07,221] [root] [WARNING] 129 HTTPConnectionPool(host='localhost', port=2990): Max retries exceeded with url: /jira/rest/api/2/serverInfo (Caused by NewConnectionError('<requests.packages.urllib3.connection.HTTPConnection object at 0x0000000003795F28>: Failed to establish a new connection: [Errno 10061] ',)) while doing GET http://localhost:2990/jira/rest/api/2/serverInfo [{u'headers': {'Accept-Encoding': 'gzip, deflate', u'Accept': u'application/json,*.*;q=0.9', 'User-Agent': 'python-requests/2.10.0', 'Connection': 'keep-alive', u'X-Atlassian-Token': u'no-check', u'Cache-Control': u'no-cache', u'Content-Type': u'application/json'}, 'params': None}]
[2017-09-15 10:58:07,224] [requests.packages.urllib3.connectionpool] [INFO] 213 Starting new HTTP connection (1): jira.jfz.net
[2017-09-15 10:58:07,431] [bugHunter] [INFO] 25 登录成功
[2017-09-15 10:58:07,433] [bugHunter] [INFO] 18 GXQ-29 符合条件，开始上传附件
[2017-09-15 10:58:07,565] [bugHunter] [INFO] 36 查询bug成功
[2017-09-15 10:58:07,796] [bugHunter] [INFO] 20 插入附件成功
[2017-09-15 10:58:07,798] [bugHunter] [INFO] 60 插入附件成功，删除本地存储的文件成功！！！
[2017-09-15 10:58:07,799] [werkzeug] [INFO] 87 10.3.10.20 - - [15/Sep/2017 10:58:07] "POST /bughunter/upload HTTP/1.1" 200 -
[2017-09-15 10:58:50,194] [werkzeug] [INFO] 87  * Detected change in 'E:\\Learn\\python\\bugHunter\\insertAttachment.py', reloading
[2017-09-15 10:58:50,221] [werkzeug] [INFO] 87  * Restarting with stat
[2017-09-15 10:59:26,292] [werkzeug] [INFO] 87  * Restarting with stat
[2017-09-15 10:59:26,525] [werkzeug] [WARNING] 87  * Debugger is active!
[2017-09-15 10:59:26,528] [werkzeug] [INFO] 87  * Debugger pin code: 100-550-078
[2017-09-15 10:59:26,536] [werkzeug] [INFO] 87  * Running on http://0.0.0.0:9528/ (Press CTRL+C to quit)
[2017-09-15 10:59:30,426] [bugHunter] [INFO] 17 文件接收并保存成功:E:\Learn\python\bugHunter\uploadFiles\5864ab29780c11505444370.png
[2017-09-15 10:59:30,426] [bugHunter] [INFO] 56 开始往jira往对应bug中插入附件,bugID:GXQ-29
[2017-09-15 10:59:30,431] [requests.packages.urllib3.connectionpool] [INFO] 213 Starting new HTTP connection (1): localhost
[2017-09-15 10:59:32,434] [root] [WARNING] 129 HTTPConnectionPool(host='localhost', port=2990): Max retries exceeded with url: /jira/rest/api/2/serverInfo (Caused by NewConnectionError('<requests.packages.urllib3.connection.HTTPConnection object at 0x0000000003945AC8>: Failed to establish a new connection: [Errno 10061] ',)) while doing GET http://localhost:2990/jira/rest/api/2/serverInfo [{u'headers': {'Accept-Encoding': 'gzip, deflate', u'Accept': u'application/json,*.*;q=0.9', 'User-Agent': 'python-requests/2.10.0', 'Connection': 'keep-alive', u'X-Atlassian-Token': u'no-check', u'Cache-Control': u'no-cache', u'Content-Type': u'application/json'}, 'params': None}]
[2017-09-15 10:59:32,434] [root] [WARNING] 86 Got ConnectionError [HTTPConnectionPool(host='localhost', port=2990): Max retries exceeded with url: /jira/rest/api/2/serverInfo (Caused by NewConnectionError('<requests.packages.urllib3.connection.HTTPConnection object at 0x0000000003945AC8>: Failed to establish a new connection: [Errno 10061] ',))] errno:None on GET http://localhost:2990/jira/rest/api/2/serverInfo
{'request': <PreparedRequest [GET]>, 'response': None}\{'request': <PreparedRequest [GET]>, 'response': None}
[2017-09-15 10:59:32,436] [root] [WARNING] 102 Got recoverable error from GET http://localhost:2990/jira/rest/api/2/serverInfo, will retry [1/3] in 13.0633419344s. Err: HTTPConnectionPool(host='localhost', port=2990): Max retries exceeded with url: /jira/rest/api/2/serverInfo (Caused by NewConnectionError('<requests.packages.urllib3.connection.HTTPConnection object at 0x0000000003945AC8>: Failed to establish a new connection: [Errno 10061] ',))
[2017-09-15 10:59:45,500] [requests.packages.urllib3.connectionpool] [INFO] 213 Starting new HTTP connection (2): localhost
[2017-09-15 10:59:47,500] [root] [WARNING] 129 HTTPConnectionPool(host='localhost', port=2990): Max retries exceeded with url: /jira/rest/api/2/serverInfo (Caused by NewConnectionError('<requests.packages.urllib3.connection.HTTPConnection object at 0x0000000003945D68>: Failed to establish a new connection: [Errno 10061] ',)) while doing GET http://localhost:2990/jira/rest/api/2/serverInfo [{u'headers': {'Accept-Encoding': 'gzip, deflate', u'Accept': u'application/json,*.*;q=0.9', 'User-Agent': 'python-requests/2.10.0', 'Connection': 'keep-alive', u'X-Atlassian-Token': u'no-check', u'Cache-Control': u'no-cache', u'Content-Type': u'application/json'}, 'params': None}]
[2017-09-15 10:59:47,502] [root] [WARNING] 86 Got ConnectionError [HTTPConnectionPool(host='localhost', port=2990): Max retries exceeded with url: /jira/rest/api/2/serverInfo (Caused by NewConnectionError('<requests.packages.urllib3.connection.HTTPConnection object at 0x0000000003945D68>: Failed to establish a new connection: [Errno 10061] ',))] errno:None on GET http://localhost:2990/jira/rest/api/2/serverInfo
{'request': <PreparedRequest [GET]>, 'response': None}\{'request': <PreparedRequest [GET]>, 'response': None}
[2017-09-15 10:59:47,502] [root] [WARNING] 102 Got recoverable error from GET http://localhost:2990/jira/rest/api/2/serverInfo, will retry [2/3] in 2.75341187909s. Err: HTTPConnectionPool(host='localhost', port=2990): Max retries exceeded with url: /jira/rest/api/2/serverInfo (Caused by NewConnectionError('<requests.packages.urllib3.connection.HTTPConnection object at 0x0000000003945D68>: Failed to establish a new connection: [Errno 10061] ',))
[2017-09-15 10:59:50,256] [requests.packages.urllib3.connectionpool] [INFO] 213 Starting new HTTP connection (3): localhost
[2017-09-15 10:59:52,265] [root] [WARNING] 129 HTTPConnectionPool(host='localhost', port=2990): Max retries exceeded with url: /jira/rest/api/2/serverInfo (Caused by NewConnectionError('<requests.packages.urllib3.connection.HTTPConnection object at 0x0000000003945E80>: Failed to establish a new connection: [Errno 10061] ',)) while doing GET http://localhost:2990/jira/rest/api/2/serverInfo [{u'headers': {'Accept-Encoding': 'gzip, deflate', u'Accept': u'application/json,*.*;q=0.9', 'User-Agent': 'python-requests/2.10.0', 'Connection': 'keep-alive', u'X-Atlassian-Token': u'no-check', u'Cache-Control': u'no-cache', u'Content-Type': u'application/json'}, 'params': None}]
[2017-09-15 10:59:52,265] [root] [WARNING] 86 Got ConnectionError [HTTPConnectionPool(host='localhost', port=2990): Max retries exceeded with url: /jira/rest/api/2/serverInfo (Caused by NewConnectionError('<requests.packages.urllib3.connection.HTTPConnection object at 0x0000000003945E80>: Failed to establish a new connection: [Errno 10061] ',))] errno:None on GET http://localhost:2990/jira/rest/api/2/serverInfo
{'request': <PreparedRequest [GET]>, 'response': None}\{'request': <PreparedRequest [GET]>, 'response': None}
[2017-09-15 10:59:52,265] [root] [WARNING] 102 Got recoverable error from GET http://localhost:2990/jira/rest/api/2/serverInfo, will retry [3/3] in 29.2725523492s. Err: HTTPConnectionPool(host='localhost', port=2990): Max retries exceeded with url: /jira/rest/api/2/serverInfo (Caused by NewConnectionError('<requests.packages.urllib3.connection.HTTPConnection object at 0x0000000003945E80>: Failed to establish a new connection: [Errno 10061] ',))
[2017-09-15 11:00:21,539] [requests.packages.urllib3.connectionpool] [INFO] 213 Starting new HTTP connection (4): localhost
[2017-09-15 11:00:23,539] [root] [WARNING] 129 HTTPConnectionPool(host='localhost', port=2990): Max retries exceeded with url: /jira/rest/api/2/serverInfo (Caused by NewConnectionError('<requests.packages.urllib3.connection.HTTPConnection object at 0x0000000003945F28>: Failed to establish a new connection: [Errno 10061] ',)) while doing GET http://localhost:2990/jira/rest/api/2/serverInfo [{u'headers': {'Accept-Encoding': 'gzip, deflate', u'Accept': u'application/json,*.*;q=0.9', 'User-Agent': 'python-requests/2.10.0', 'Connection': 'keep-alive', u'X-Atlassian-Token': u'no-check', u'Cache-Control': u'no-cache', u'Content-Type': u'application/json'}, 'params': None}]
[2017-09-15 11:00:23,546] [requests.packages.urllib3.connectionpool] [INFO] 213 Starting new HTTP connection (1): jira.jfz.net
[2017-09-15 11:00:23,739] [bugHunter] [INFO] 25 登录成功
[2017-09-15 11:00:23,739] [bugHunter] [INFO] 18 GXQ-29 符合条件，开始上传附件
[2017-09-15 11:00:23,881] [bugHunter] [INFO] 36 查询bug成功
[2017-09-15 11:00:24,118] [bugHunter] [INFO] 20 插入附件成功
[2017-09-15 11:00:24,119] [bugHunter] [INFO] 60 插入附件成功，删除本地存储的文件成功！！！
[2017-09-15 11:00:24,121] [werkzeug] [INFO] 87 10.3.10.20 - - [15/Sep/2017 11:00:24] "POST /bughunter/upload HTTP/1.1" 200 -
[2017-09-15 11:00:37,155] [bugHunter] [INFO] 17 文件接收并保存成功:E:\Learn\python\bugHunter\uploadFiles\5864ab29780c11505444437.png
[2017-09-15 11:00:37,155] [bugHunter] [INFO] 56 开始往jira往对应bug中插入附件,bugID:GXQ-29
[2017-09-15 11:00:37,160] [requests.packages.urllib3.connectionpool] [INFO] 213 Starting new HTTP connection (1): localhost
[2017-09-15 11:00:39,180] [root] [WARNING] 129 HTTPConnectionPool(host='localhost', port=2990): Max retries exceeded with url: /jira/rest/api/2/serverInfo (Caused by NewConnectionError('<requests.packages.urllib3.connection.HTTPConnection object at 0x000000000397D518>: Failed to establish a new connection: [Errno 10061] ',)) while doing GET http://localhost:2990/jira/rest/api/2/serverInfo [{u'headers': {'Accept-Encoding': 'gzip, deflate', u'Accept': u'application/json,*.*;q=0.9', 'User-Agent': 'python-requests/2.10.0', 'Connection': 'keep-alive', u'X-Atlassian-Token': u'no-check', u'Cache-Control': u'no-cache', u'Content-Type': u'application/json'}, 'params': None}]
[2017-09-15 11:00:39,180] [root] [WARNING] 86 Got ConnectionError [HTTPConnectionPool(host='localhost', port=2990): Max retries exceeded with url: /jira/rest/api/2/serverInfo (Caused by NewConnectionError('<requests.packages.urllib3.connection.HTTPConnection object at 0x000000000397D518>: Failed to establish a new connection: [Errno 10061] ',))] errno:None on GET http://localhost:2990/jira/rest/api/2/serverInfo
{'request': <PreparedRequest [GET]>, 'response': None}\{'request': <PreparedRequest [GET]>, 'response': None}
[2017-09-15 11:00:39,180] [root] [WARNING] 102 Got recoverable error from GET http://localhost:2990/jira/rest/api/2/serverInfo, will retry [1/3] in 5.71583715291s. Err: HTTPConnectionPool(host='localhost', port=2990): Max retries exceeded with url: /jira/rest/api/2/serverInfo (Caused by NewConnectionError('<requests.packages.urllib3.connection.HTTPConnection object at 0x000000000397D518>: Failed to establish a new connection: [Errno 10061] ',))
[2017-09-15 11:00:44,897] [requests.packages.urllib3.connectionpool] [INFO] 213 Starting new HTTP connection (2): localhost
[2017-09-15 11:00:46,898] [root] [WARNING] 129 HTTPConnectionPool(host='localhost', port=2990): Max retries exceeded with url: /jira/rest/api/2/serverInfo (Caused by NewConnectionError('<requests.packages.urllib3.connection.HTTPConnection object at 0x000000000397D668>: Failed to establish a new connection: [Errno 10061] ',)) while doing GET http://localhost:2990/jira/rest/api/2/serverInfo [{u'headers': {'Accept-Encoding': 'gzip, deflate', u'Accept': u'application/json,*.*;q=0.9', 'User-Agent': 'python-requests/2.10.0', 'Connection': 'keep-alive', u'X-Atlassian-Token': u'no-check', u'Cache-Control': u'no-cache', u'Content-Type': u'application/json'}, 'params': None}]
[2017-09-15 11:00:46,898] [root] [WARNING] 86 Got ConnectionError [HTTPConnectionPool(host='localhost', port=2990): Max retries exceeded with url: /jira/rest/api/2/serverInfo (Caused by NewConnectionError('<requests.packages.urllib3.connection.HTTPConnection object at 0x000000000397D668>: Failed to establish a new connection: [Errno 10061] ',))] errno:None on GET http://localhost:2990/jira/rest/api/2/serverInfo
{'request': <PreparedRequest [GET]>, 'response': None}\{'request': <PreparedRequest [GET]>, 'response': None}
[2017-09-15 11:00:46,898] [root] [WARNING] 102 Got recoverable error from GET http://localhost:2990/jira/rest/api/2/serverInfo, will retry [2/3] in 16.3372406857s. Err: HTTPConnectionPool(host='localhost', port=2990): Max retries exceeded with url: /jira/rest/api/2/serverInfo (Caused by NewConnectionError('<requests.packages.urllib3.connection.HTTPConnection object at 0x000000000397D668>: Failed to establish a new connection: [Errno 10061] ',))
[2017-09-15 11:01:03,240] [requests.packages.urllib3.connectionpool] [INFO] 213 Starting new HTTP connection (3): localhost
[2017-09-15 11:01:05,253] [root] [WARNING] 129 HTTPConnectionPool(host='localhost', port=2990): Max retries exceeded with url: /jira/rest/api/2/serverInfo (Caused by NewConnectionError('<requests.packages.urllib3.connection.HTTPConnection object at 0x0000000003945A20>: Failed to establish a new connection: [Errno 10061] ',)) while doing GET http://localhost:2990/jira/rest/api/2/serverInfo [{u'headers': {'Accept-Encoding': 'gzip, deflate', u'Accept': u'application/json,*.*;q=0.9', 'User-Agent': 'python-requests/2.10.0', 'Connection': 'keep-alive', u'X-Atlassian-Token': u'no-check', u'Cache-Control': u'no-cache', u'Content-Type': u'application/json'}, 'params': None}]
[2017-09-15 11:01:05,255] [root] [WARNING] 86 Got ConnectionError [HTTPConnectionPool(host='localhost', port=2990): Max retries exceeded with url: /jira/rest/api/2/serverInfo (Caused by NewConnectionError('<requests.packages.urllib3.connection.HTTPConnection object at 0x0000000003945A20>: Failed to establish a new connection: [Errno 10061] ',))] errno:None on GET http://localhost:2990/jira/rest/api/2/serverInfo
{'request': <PreparedRequest [GET]>, 'response': None}\{'request': <PreparedRequest [GET]>, 'response': None}
[2017-09-15 11:01:05,255] [root] [WARNING] 102 Got recoverable error from GET http://localhost:2990/jira/rest/api/2/serverInfo, will retry [3/3] in 1.33310456017s. Err: HTTPConnectionPool(host='localhost', port=2990): Max retries exceeded with url: /jira/rest/api/2/serverInfo (Caused by NewConnectionError('<requests.packages.urllib3.connection.HTTPConnection object at 0x0000000003945A20>: Failed to establish a new connection: [Errno 10061] ',))
[2017-09-15 11:01:06,588] [requests.packages.urllib3.connectionpool] [INFO] 213 Starting new HTTP connection (4): localhost
[2017-09-15 11:01:08,582] [root] [WARNING] 129 HTTPConnectionPool(host='localhost', port=2990): Max retries exceeded with url: /jira/rest/api/2/serverInfo (Caused by NewConnectionError('<requests.packages.urllib3.connection.HTTPConnection object at 0x000000000397D7B8>: Failed to establish a new connection: [Errno 10061] ',)) while doing GET http://localhost:2990/jira/rest/api/2/serverInfo [{u'headers': {'Accept-Encoding': 'gzip, deflate', u'Accept': u'application/json,*.*;q=0.9', 'User-Agent': 'python-requests/2.10.0', 'Connection': 'keep-alive', u'X-Atlassian-Token': u'no-check', u'Cache-Control': u'no-cache', u'Content-Type': u'application/json'}, 'params': None}]
[2017-09-15 11:01:08,585] [requests.packages.urllib3.connectionpool] [INFO] 213 Starting new HTTP connection (1): jira.jfz.net
[2017-09-15 11:01:08,770] [bugHunter] [INFO] 25 登录成功
[2017-09-15 11:01:08,770] [bugHunter] [INFO] 18 GXQ-29 符合条件，开始上传附件
[2017-09-15 11:01:08,920] [bugHunter] [INFO] 36 查询bug成功
[2017-09-15 11:01:09,131] [bugHunter] [INFO] 20 插入附件成功
[2017-09-15 11:01:09,132] [bugHunter] [INFO] 60 插入附件成功，删除本地存储的文件成功！！！
[2017-09-15 11:01:09,132] [werkzeug] [INFO] 87 10.3.10.20 - - [15/Sep/2017 11:01:09] "POST /bughunter/upload HTTP/1.1" 200 -
[2017-10-10 09:59:19,953] [werkzeug] [INFO] 87  * Restarting with stat
[2017-10-10 09:59:20,211] [werkzeug] [WARNING] 87  * Debugger is active!
[2017-10-10 09:59:20,236] [werkzeug] [INFO] 87  * Debugger pin code: 100-550-078
[2017-10-10 09:59:20,278] [werkzeug] [INFO] 87  * Running on http://0.0.0.0:9528/ (Press CTRL+C to quit)
[2017-10-10 10:00:27,253] [bugHunter] [INFO] 17 文件接收并保存成功:E:\Learn\python\bugHunter\uploadFiles\5864ab29780c11507600827.png
[2017-10-10 10:00:27,253] [bugHunter] [INFO] 56 开始往jira往对应bug中插入附件,bugID:GXQ-23
[2017-10-10 10:00:27,315] [requests.packages.urllib3.connectionpool] [INFO] 213 Starting new HTTP connection (1): 127.0.0.1
[2017-10-10 10:00:27,526] [bugHunter] [INFO] 25 登录成功
[2017-10-10 10:00:27,526] [bugHunter] [INFO] 18 GXQ-23 符合条件，开始上传附件
[2017-10-10 10:00:27,660] [bugHunter] [INFO] 36 查询bug成功
[2017-10-10 10:00:27,920] [bugHunter] [INFO] 20 插入附件成功
[2017-10-10 10:00:27,924] [bugHunter] [INFO] 60 插入附件成功，删除本地存储的文件成功！！！
[2017-10-10 10:00:27,924] [werkzeug] [INFO] 87 10.3.10.20 - - [10/Oct/2017 10:00:27] "POST /bughunter/upload HTTP/1.1" 200 -
[2017-10-10 10:07:17,469] [werkzeug] [INFO] 87  * Restarting with stat
[2017-10-10 10:07:17,910] [werkzeug] [WARNING] 87  * Debugger is active!
[2017-10-10 10:07:17,914] [werkzeug] [INFO] 87  * Debugger pin code: 100-550-078
[2017-10-10 10:07:17,921] [werkzeug] [INFO] 87  * Running on http://0.0.0.0:9528/ (Press CTRL+C to quit)
[2017-10-10 10:07:24,982] [bugHunter] [INFO] 17 文件接收并保存成功:E:\Learn\python\bugHunter\uploadFiles\5864ab29780c11507601244.png
[2017-10-10 10:07:24,982] [bugHunter] [INFO] 57 开始往jira往对应bug中插入附件,bugID:GXQ-23
[2017-10-10 10:07:24,986] [requests.packages.urllib3.connectionpool] [INFO] 213 Starting new HTTP connection (1): 127.0.0.1
[2017-10-10 10:07:25,207] [bugHunter] [INFO] 25 登录成功
[2017-10-10 10:07:25,209] [bugHunter] [INFO] 18 GXQ-23 符合条件，开始上传附件
[2017-10-10 10:07:25,358] [bugHunter] [INFO] 36 查询bug成功
[2017-10-10 10:07:25,579] [bugHunter] [INFO] 20 插入附件成功
[2017-10-10 10:07:25,581] [bugHunter] [INFO] 61 插入附件成功，删除本地存储的文件成功！！！
[2017-10-10 10:07:25,581] [werkzeug] [INFO] 87 10.3.10.20 - - [10/Oct/2017 10:07:25] "POST /bughunter/upload HTTP/1.1" 200 -
[2017-10-10 10:07:52,466] [werkzeug] [INFO] 87  * Detected change in 'E:\\Learn\\python\\bugHunter\\start.py', reloading
[2017-10-10 10:07:52,484] [werkzeug] [INFO] 87  * Restarting with stat
[2017-10-10 10:07:52,706] [werkzeug] [WARNING] 87  * Debugger is active!
[2017-10-10 10:07:52,710] [werkzeug] [INFO] 87  * Debugger pin code: 100-550-078
[2017-10-10 10:07:52,716] [werkzeug] [INFO] 87  * Running on http://0.0.0.0:9528/ (Press CTRL+C to quit)
[2017-10-10 10:08:04,005] [werkzeug] [INFO] 87  * Detected change in 'E:\\Learn\\python\\bugHunter\\start.py', reloading
[2017-10-10 10:08:04,046] [werkzeug] [INFO] 87  * Restarting with stat
[2017-10-10 10:08:04,375] [werkzeug] [WARNING] 87  * Debugger is active!
[2017-10-10 10:08:04,378] [werkzeug] [INFO] 87  * Debugger pin code: 100-550-078
[2017-10-10 10:08:04,384] [werkzeug] [INFO] 87  * Running on http://0.0.0.0:9528/ (Press CTRL+C to quit)
[2018-01-04 14:45:52,246] [werkzeug] [INFO] 87  * Restarting with stat
[2018-01-04 14:45:52,525] [werkzeug] [WARNING] 87  * Debugger is active!
[2018-01-04 14:45:52,555] [werkzeug] [INFO] 87  * Debugger pin code: 100-550-078
[2018-01-04 14:45:52,619] [werkzeug] [INFO] 87  * Running on http://0.0.0.0:9528/ (Press CTRL+C to quit)
[2018-01-04 14:45:58,359] [werkzeug] [INFO] 87 10.3.10.20 - - [04/Jan/2018 14:45:58] "GET / HTTP/1.1" 404 -
[2018-01-04 14:45:58,421] [werkzeug] [INFO] 87 10.3.10.20 - - [04/Jan/2018 14:45:58] "GET / HTTP/1.1" 404 -
[2018-01-04 14:45:59,063] [werkzeug] [INFO] 87 10.3.10.20 - - [04/Jan/2018 14:45:59] "GET /favicon.ico HTTP/1.1" 404 -
[2018-01-04 14:45:59,079] [werkzeug] [INFO] 87 10.3.10.20 - - [04/Jan/2018 14:45:59] "GET /favicon.ico HTTP/1.1" 404 -
[2018-01-04 14:46:07,598] [werkzeug] [INFO] 87 10.3.10.20 - - [04/Jan/2018 14:46:07] "GET /test/upload HTTP/1.1" 200 -
[2018-01-04 18:09:19,226] [werkzeug] [INFO] 87  * Restarting with stat
[2018-01-04 18:09:20,326] [werkzeug] [WARNING] 87  * Debugger is active!
[2018-01-04 18:09:20,329] [werkzeug] [INFO] 87  * Debugger pin code: 100-550-078
[2018-01-04 18:09:20,354] [werkzeug] [INFO] 87  * Running on http://0.0.0.0:9528/ (Press CTRL+C to quit)
[2018-01-04 18:09:42,467] [werkzeug] [INFO] 87 10.3.10.20 - - [04/Jan/2018 18:09:42] "GET / HTTP/1.1" 404 -
[2018-01-04 18:09:52,375] [werkzeug] [INFO] 87 10.3.10.20 - - [04/Jan/2018 18:09:52] "GET /test/upload HTTP/1.1" 200 -
[2018-01-04 18:10:16,154] [bugHunter] [INFO] 17 文件接收并保存成功:E:\Learn\python\bugHunter\uploadFiles\5864ab29780c11515060616.png
[2018-01-04 18:10:16,154] [bugHunter] [INFO] 58 开始往jira往对应bug中插入附件,bugID:GXQ-23
[2018-01-04 18:10:16,229] [requests.packages.urllib3.connectionpool] [INFO] 213 Starting new HTTP connection (1): 127.0.0.1
[2018-01-04 18:10:16,471] [bugHunter] [INFO] 25 登录成功
[2018-01-04 18:10:16,471] [bugHunter] [INFO] 18 GXQ-23 符合条件，开始上传附件
[2018-01-04 18:10:16,642] [bugHunter] [INFO] 37 查询bug成功
[2018-01-04 18:10:16,905] [bugHunter] [INFO] 21 插入附件成功
[2018-01-04 18:10:16,907] [bugHunter] [INFO] 62 插入附件成功，删除本地存储的文件成功！！！
[2018-01-04 18:10:16,907] [werkzeug] [INFO] 87 10.3.10.20 - - [04/Jan/2018 18:10:16] "POST /bughunter/upload HTTP/1.1" 200 -
